11/04/2014 16:00:09: DEBUG 11  Generic Logger - An exception has been thrown by: UserController in action: GetUserExternalToken
System.Web.Http.HttpResponseException: Processing of the HTTP request resulted in an exception. Please see the HTTP response returned by the 'Response' property of this exception for details.
   at System.Web.Http.ModelBinding.FormatterParameterBinding.ReadContentAsync(HttpRequestMessage request, Type type, IEnumerable`1 formatters, IFormatterLogger formatterLogger, CancellationToken cancellationToken)
   at System.Web.Http.ModelBinding.FormatterParameterBinding.ReadContentAsync(HttpRequestMessage request, Type type, IEnumerable`1 formatters, IFormatterLogger formatterLogger)
   at System.Web.Http.ModelBinding.FormatterParameterBinding.<ExecuteBindingAsyncCore>d__0.MoveNext()
--- End of stack trace from previous location where exception was thrown ---
   at System.Runtime.CompilerServices.TaskAwaiter.ThrowForNonSuccess(Task task)
   at System.Runtime.CompilerServices.TaskAwaiter.HandleNonSuccessAndDebuggerNotification(Task task)
   at System.Runtime.CompilerServices.TaskAwaiter.GetResult()
   at System.Web.Http.Controllers.HttpActionBinding.<ExecuteBindingAsyncCore>d__0.MoveNext()
--- End of stack trace from previous location where exception was thrown ---
   at System.Runtime.CompilerServices.TaskAwaiter.ThrowForNonSuccess(Task task)
   at System.Runtime.CompilerServices.TaskAwaiter.HandleNonSuccessAndDebuggerNotification(Task task)
   at System.Runtime.CompilerServices.TaskAwaiter.GetResult()
   at System.Web.Http.Controllers.ActionFilterResult.<ExecuteAsync>d__2.MoveNext()
--- End of stack trace from previous location where exception was thrown ---
   at System.Runtime.CompilerServices.TaskAwaiter.ThrowForNonSuccess(Task task)
   at System.Runtime.CompilerServices.TaskAwaiter.HandleNonSuccessAndDebuggerNotification(Task task)
   at System.Runtime.CompilerServices.TaskAwaiter`1.GetResult()
   at System.Web.Http.Controllers.ExceptionFilterResult.<ExecuteAsync>d__0.MoveNext()
11/04/2014 16:00:47: DEBUG 8  Generic Logger - Starting operation: User / GetUserExternalToken
11/04/2014 16:01:03: DEBUG 8  Generic Logger - Ending operation: User / GetUserExternalToken
11/04/2014 16:01:03: INFO 8  Generic Logger - =========================================================================================================
11/04/2014 16:01:03: INFO 8  Generic Logger - =========================================================================================================
11/04/2014 16:01:03: INFO 8  Generic Logger - =========================================================================================================
11/04/2014 16:01:03: DEBUG 8  Generic Logger - An exception has been thrown by: UserController in action: GetUserExternalToken
System.NullReferenceException: Object reference not set to an instance of an object.
   at CoreService.Controllers.UserController.GetUserExternalToken(LoginDataModel loginData) in d:\Projects\Virtual Office\VirtualOffice\CoreService\Controllers\UserController.cs:line 63
   at lambda_method(Closure , Object , Object[] )
   at System.Web.Http.Controllers.ReflectedHttpActionDescriptor.ActionExecutor.<>c__DisplayClass10.<GetExecutor>b__9(Object instance, Object[] methodParameters)
   at System.Web.Http.Controllers.ReflectedHttpActionDescriptor.ActionExecutor.Execute(Object instance, Object[] arguments)
   at System.Web.Http.Controllers.ReflectedHttpActionDescriptor.ExecuteAsync(HttpControllerContext controllerContext, IDictionary`2 arguments, CancellationToken cancellationToken)
--- End of stack trace from previous location where exception was thrown ---
   at System.Runtime.CompilerServices.TaskAwaiter.ThrowForNonSuccess(Task task)
   at System.Runtime.CompilerServices.TaskAwaiter.HandleNonSuccessAndDebuggerNotification(Task task)
   at System.Runtime.CompilerServices.TaskAwaiter`1.GetResult()
   at System.Web.Http.Controllers.ApiControllerActionInvoker.<InvokeActionAsyncCore>d__0.MoveNext()
--- End of stack trace from previous location where exception was thrown ---
   at System.Runtime.CompilerServices.TaskAwaiter.ThrowForNonSuccess(Task task)
   at System.Runtime.CompilerServices.TaskAwaiter.HandleNonSuccessAndDebuggerNotification(Task task)
   at System.Runtime.CompilerServices.TaskAwaiter`1.GetResult()
   at System.Web.Http.Filters.ActionFilterAttribute.<CallOnActionExecutedAsync>d__5.MoveNext()
--- End of stack trace from previous location where exception was thrown ---
   at System.Runtime.ExceptionServices.ExceptionDispatchInfo.Throw()
   at System.Web.Http.Filters.ActionFilterAttribute.<CallOnActionExecutedAsync>d__5.MoveNext()
--- End of stack trace from previous location where exception was thrown ---
   at System.Runtime.CompilerServices.TaskAwaiter.ThrowForNonSuccess(Task task)
   at System.Runtime.CompilerServices.TaskAwaiter.HandleNonSuccessAndDebuggerNotification(Task task)
   at System.Runtime.CompilerServices.TaskAwaiter`1.GetResult()
   at System.Web.Http.Filters.ActionFilterAttribute.<ExecuteActionFilterAsyncCore>d__0.MoveNext()
--- End of stack trace from previous location where exception was thrown ---
   at System.Runtime.CompilerServices.TaskAwaiter.ThrowForNonSuccess(Task task)
   at System.Runtime.CompilerServices.TaskAwaiter.HandleNonSuccessAndDebuggerNotification(Task task)
   at System.Runtime.CompilerServices.TaskAwaiter`1.GetResult()
   at System.Web.Http.Controllers.ActionFilterResult.<ExecuteAsync>d__2.MoveNext()
--- End of stack trace from previous location where exception was thrown ---
   at System.Runtime.CompilerServices.TaskAwaiter.ThrowForNonSuccess(Task task)
   at System.Runtime.CompilerServices.TaskAwaiter.HandleNonSuccessAndDebuggerNotification(Task task)
   at System.Runtime.CompilerServices.TaskAwaiter`1.GetResult()
   at System.Web.Http.Controllers.ExceptionFilterResult.<ExecuteAsync>d__0.MoveNext()
11/04/2014 16:01:13: DEBUG 8  Generic Logger - An exception has been thrown by: UserController in action: GetUserExternalToken
System.Web.Http.HttpResponseException: Processing of the HTTP request resulted in an exception. Please see the HTTP response returned by the 'Response' property of this exception for details.
   at System.Web.Http.ModelBinding.FormatterParameterBinding.ReadContentAsync(HttpRequestMessage request, Type type, IEnumerable`1 formatters, IFormatterLogger formatterLogger, CancellationToken cancellationToken)
   at System.Web.Http.ModelBinding.FormatterParameterBinding.ReadContentAsync(HttpRequestMessage request, Type type, IEnumerable`1 formatters, IFormatterLogger formatterLogger)
   at System.Web.Http.ModelBinding.FormatterParameterBinding.<ExecuteBindingAsyncCore>d__0.MoveNext()
--- End of stack trace from previous location where exception was thrown ---
   at System.Runtime.CompilerServices.TaskAwaiter.ThrowForNonSuccess(Task task)
   at System.Runtime.CompilerServices.TaskAwaiter.HandleNonSuccessAndDebuggerNotification(Task task)
   at System.Runtime.CompilerServices.TaskAwaiter.GetResult()
   at System.Web.Http.Controllers.HttpActionBinding.<ExecuteBindingAsyncCore>d__0.MoveNext()
--- End of stack trace from previous location where exception was thrown ---
   at System.Runtime.CompilerServices.TaskAwaiter.ThrowForNonSuccess(Task task)
   at System.Runtime.CompilerServices.TaskAwaiter.HandleNonSuccessAndDebuggerNotification(Task task)
   at System.Runtime.CompilerServices.TaskAwaiter.GetResult()
   at System.Web.Http.Controllers.ActionFilterResult.<ExecuteAsync>d__2.MoveNext()
--- End of stack trace from previous location where exception was thrown ---
   at System.Runtime.CompilerServices.TaskAwaiter.ThrowForNonSuccess(Task task)
   at System.Runtime.CompilerServices.TaskAwaiter.HandleNonSuccessAndDebuggerNotification(Task task)
   at System.Runtime.CompilerServices.TaskAwaiter`1.GetResult()
   at System.Web.Http.Controllers.ExceptionFilterResult.<ExecuteAsync>d__0.MoveNext()
